Traceback (most recent call last):
  File "/mmfs1/cm/shared/apps_local/python/3.11/envs/tensorflow/lib/python3.11/site-packages/pandas/core/indexes/base.py", line 3805, in get_loc
    return self._engine.get_loc(casted_key)
           ^^^^^^^^^^^^^^^^^^^^^^^^^^^^^^^^
  File "index.pyx", line 167, in pandas._libs.index.IndexEngine.get_loc
  File "index.pyx", line 196, in pandas._libs.index.IndexEngine.get_loc
  File "pandas/_libs/hashtable_class_helper.pxi", line 7081, in pandas._libs.hashtable.PyObjectHashTable.get_item
  File "pandas/_libs/hashtable_class_helper.pxi", line 7089, in pandas._libs.hashtable.PyObjectHashTable.get_item
KeyError: 'y'

The above exception was the direct cause of the following exception:

Traceback (most recent call last):
  File "/mmfs1/home/jacks.local/cpatten/ContrastiveLearning_NBIDE/code/import_images.py", line 14, in <module>
    images_dict[im.replace('.csv','')] = image.pivot(index='y', columns='x', values='value')
                                         ^^^^^^^^^^^^^^^^^^^^^^^^^^^^^^^^^^^^^^^^^^^^^^^^^^^
  File "/mmfs1/cm/shared/apps_local/python/3.11/envs/tensorflow/lib/python3.11/site-packages/pandas/core/frame.py", line 9326, in pivot
    return pivot(self, index=index, columns=columns, values=values)
           ^^^^^^^^^^^^^^^^^^^^^^^^^^^^^^^^^^^^^^^^^^^^^^^^^^^^^^^^
  File "/mmfs1/cm/shared/apps_local/python/3.11/envs/tensorflow/lib/python3.11/site-packages/pandas/core/reshape/pivot.py", line 553, in pivot
    index_list = [data[idx] for idx in com.convert_to_list_like(index)]
                 ^^^^^^^^^^^^^^^^^^^^^^^^^^^^^^^^^^^^^^^^^^^^^^^^^^^^^^
  File "/mmfs1/cm/shared/apps_local/python/3.11/envs/tensorflow/lib/python3.11/site-packages/pandas/core/reshape/pivot.py", line 553, in <listcomp>
    index_list = [data[idx] for idx in com.convert_to_list_like(index)]
                  ~~~~^^^^^
  File "/mmfs1/cm/shared/apps_local/python/3.11/envs/tensorflow/lib/python3.11/site-packages/pandas/core/frame.py", line 4090, in __getitem__
    indexer = self.columns.get_loc(key)
              ^^^^^^^^^^^^^^^^^^^^^^^^^
  File "/mmfs1/cm/shared/apps_local/python/3.11/envs/tensorflow/lib/python3.11/site-packages/pandas/core/indexes/base.py", line 3812, in get_loc
    raise KeyError(key) from err
KeyError: 'y'
